<?xml version="1.0"?>

<robot xmlns:xacro="http://www.ros.org/wiki/xacro">

    <xacro:property name="M_PI" value="3.1415926535897931" />
    <xacro:macro name="Lite3" params="has_lidar:=false lidar_hz:=10 lidar_horizontal_samples:=3600 lidar_channels:=16 lidar_min_range:=0.3 lidar_max_range:=130.0 lidar_noise:=0.008">

    <xacro:include filename="$(find lite3_description)/xacro/imu_link.xacro"/>

    <link name="TORSO">
      <visual>
        <origin rpy="1.5708 0 1.5708" xyz="-0.05 -0.5 0.08"/>
        <geometry>
          <mesh filename="package://lite3_description/meshes/TORSO.dae" />
        </geometry>
      </visual>
      <collision>
        <geometry>
          <box size="0.234 0.184 0.08"/>
        </geometry>
      </collision>
    </link>

    <link name="INERTIA">
      <inertial>
        <origin xyz="0.004098 -0.000663 -0.002069" />
        <mass value="4.130" />
        <inertia ixx="0.016982120" ixy="2.1294E-05" ixz="6.0763E-05" iyy="0.030466501" iyz="1.7968E-05" izz="0.042609956" />
      </inertial>
    </link>

    <joint name="Torso2Inertia" type="fixed">
      <parent link="TORSO" />
      <child link="INERTIA" />
    </joint>

    <link name="FL_HIP">
      <inertial>
        <origin xyz="-0.0047 -0.0091 -0.0018" />
        <mass value="0.428" />
        <inertia ixx="0.00014538" ixy="8.1579E-07" ixz="-1.264E-05" iyy="0.00024024" iyz="1.3443E-06" izz="0.00013038" />
      </inertial>
      <visual>
        <origin rpy="1.5708 0 1.5708" xyz="-0.231 -0.5625 0.08"/>
        <geometry>
          <mesh filename="package://lite3_description/meshes/FL_HIP.dae" />
        </geometry>
      </visual>
    </link>

    <joint name="FL_HipX" type="revolute">
      <origin xyz="0.1745 0.062 0" />
      <parent link="TORSO" />
      <child link="FL_HIP" />
      <axis xyz="-1 0 0" />
      <limit lower="-0.523" upper="0.523" effort="40" velocity="30" />
       <dynamics damping="2" friction="6.5"/>
    </joint>

    <link name="FL_THIGH">
      <inertial>
        <origin xyz="-0.00523 -0.0216 -0.0273" />
        <mass value="0.61" />
        <inertia ixx="0.001" ixy="-2.5E-06" ixz="-1.12E-04" iyy="0.00116" iyz="3.75E-07" izz="2.68E-04" />
      </inertial>
      <visual>
        <origin rpy="-2.0 0 1.5708" xyz="0.265 -0.66 0.011"/>
        <geometry>
          <mesh filename="package://lite3_description/meshes/L_THIGH.dae" />
        </geometry>
      </visual>
      <collision>
        <origin xyz="0 0 -0.08"/>
        <geometry>
          <box size="0.02 0.02 0.16"/>
        </geometry>
      </collision>
    </link>

    <joint name="FL_HipY" type="revolute">
      <origin xyz="0 0.0985 0" />
      <parent link="FL_HIP" />
      <child link="FL_THIGH" />
      <axis xyz="0 -1 0" />
      <limit lower="-2.67" upper="0.314" effort="40" velocity="30" />
       <dynamics damping="2" friction="6.5"/>
    </joint>

    <link name="FL_SHANK">
      <inertial>
        <origin xyz="0.00585 -8.732E-07 -0.12" />
        <mass value="0.115" />
        <inertia ixx="6.68E-04" ixy="-1.24E-08" ixz="6.91E-06" iyy="6.86E-04" iyz="5.65E-09" izz="3.155E-05" />
      </inertial>
      <visual>
      <origin xyz="0 0 -0.03"/>
        <geometry>
          <mesh filename="package://lite3_description/meshes/SHANK.dae" />
        </geometry>
      </visual>
      <collision>
        <origin xyz="0 0 -0.09"/>
        <geometry>
          <box size="0.02 0.02 0.20"/>
        </geometry>
      </collision>
    </link>

    <joint name="FL_Knee" type="revolute">
      <origin xyz="0 0 -0.20" />
      <parent link="FL_THIGH" />
      <child link="FL_SHANK" />
      <axis xyz="0 -1 0" />
      <limit lower="0.524" upper="2.792" effort="65" velocity="20" />
       <dynamics damping="2" friction="6.5"/>
    </joint>

    <link name="FL_FOOT">
      <inertial>
        <mass value="1E-12" />
        <inertia ixx="1E-12" ixy="0" ixz="0" iyy="1E-12" iyz="0" izz="1E-12" />
      </inertial>
      <collision>
        <geometry>
          <sphere radius="0.013"/>
        </geometry>
      </collision>
    </link>

    <joint name="FL_Ankle" type="fixed">
      <origin xyz="0 0 -0.21"/>
      <parent link="FL_SHANK" />
      <child link="FL_FOOT" />
    </joint>

    <link name="FR_HIP">
      <inertial>
        <origin xyz="-0.0047 0.0091 -0.0018" />
        <mass value="0.428" />
        <inertia ixx="0.00014538" ixy="-8.1551E-07" ixz="-1.2639E-05" iyy="0.00024024" iyz="-1.3441E-06" izz="0.00013038" />
      </inertial>
      <visual>
        <origin rpy="1.5708 0 1.5708" xyz="-0.231 -0.446 0.0835"/>
        <geometry>
          <mesh filename="package://lite3_description/meshes/FR_HIP.dae" />
        </geometry>
      </visual>
    </link>

    <joint name="FR_HipX" type="revolute">
      <origin xyz="0.1745 -0.062 0" />
      <parent link="TORSO" />
      <child link="FR_HIP" />
      <axis xyz="-1 0 0" />
      <limit lower="-0.523" upper="0.523" effort="40" velocity="30" />
      <dynamics damping="2" friction="6.5"/>
    </joint>

    <link name="FR_THIGH">
      <inertial>
        <origin xyz="-0.00523 0.0216 -0.0273" />
        <mass value="0.61" />
        <inertia ixx="0.001" ixy="2.5E-06" ixz="-1.12E-04" iyy="0.00116" iyz="-3.75E-07" izz="2.68E-04" />
      </inertial>
      <visual>
        <origin rpy="-2.0 0 1.5708" xyz="0.265 -0.35 0.011"/>

        <geometry>
          <mesh filename="package://lite3_description/meshes/R_THIGH.dae" />
        </geometry>
      </visual>
      <collision>
        <origin xyz="0 0 -0.08"/>
        <geometry>
          <box size="0.02 0.02 0.16"/>
        </geometry>
      </collision>
    </link>

    <joint name="FR_HipY" type="revolute">
      <origin xyz="0 -0.0985 0" />
      <parent link="FR_HIP" />
      <child link="FR_THIGH" />
      <axis xyz="0 -1 0" />
      <limit lower="-2.67" upper="0.314" effort="40" velocity="30" />
       <dynamics damping="2" friction="6.5"/>
    </joint>

    <link name="FR_SHANK">
      <inertial>
        <origin xyz="0.00585 -8.732E-07 -0.12" />
        <mass value="0.115" />
        <inertia ixx="6.68E-04" ixy="-1.24E-08" ixz="6.91E-06" iyy="6.86E-04" iyz="5.65E-09" izz="3.155E-05" />
      </inertial>
      <visual>
      <origin xyz="0 0 -0.03"/>
        <geometry>
          <mesh filename="package://lite3_description/meshes/SHANK.dae" />
        </geometry>
      </visual>
      <collision>
        <origin xyz="0 0 -0.09"/>
        <geometry>
          <box size="0.02 0.02 0.20"/>
        </geometry>
      </collision>
    </link>

    <joint name="FR_Knee" type="revolute">
      <origin xyz="0 0 -0.20" />
      <parent link="FR_THIGH" />
      <child link="FR_SHANK" />
      <axis xyz="0 -1 0" />
      <limit lower="0.524" upper="2.792" effort="65" velocity="20" />
       <dynamics damping="2" friction="6.5"/>
    </joint>

    <link name="FR_FOOT">
      <inertial>
        <mass value="1E-12" />
        <inertia ixx="1E-12" ixy="0" ixz="0" iyy="1E-12" iyz="0" izz="1E-12" />
      </inertial>
      <collision>
        <geometry>
          <sphere radius="0.013"/>
        </geometry>
      </collision>
    </link>

    <joint name="FR_Ankle" type="fixed">
      <origin xyz="0 0 -0.21"/>
      <parent link="FR_SHANK" />
      <child link="FR_FOOT" />
    </joint>

    <link name="HL_HIP">
      <inertial>
        <origin xyz="0.0047 -0.0091 -0.0018" />
        <mass value="0.428" />
        <inertia ixx="0.00014538" ixy="-8.1585E-07" ixz="1.2639E-05" iyy="0.00024024" iyz="1.3444E-06" izz="0.00013038" />
      </inertial>
      <visual>
        <origin rpy="1.5708 0 1.5708" xyz="0.12 -0.5625 0.09"/>
        <!-- <origin rpy="1.5708 0 1.5708" xyz="-0.231 -0.5625 0.08"/> -->
        <geometry>
          <mesh filename="package://lite3_description/meshes/HL_HIP.dae" />
        </geometry>
      </visual>
    </link>

    <joint name="HL_HipX" type="revolute">
      <origin xyz="-0.1745 0.062 0" />
      <parent link="TORSO" />
      <child link="HL_HIP" />
      <axis xyz="-1 0 0" />
      <limit lower="-0.523" upper="0.523" effort="40" velocity="30" />
       <dynamics damping="2" friction="6.5"/>
    </joint>

    <link name="HL_THIGH">
      <inertial>
        <origin xyz="-0.00523 -0.0216 -0.0273" />
        <mass value="0.61" />
        <inertia ixx="0.001" ixy="-2.5E-06" ixz="-1.12E-04" iyy="0.00116" iyz="3.75E-07" izz="2.68E-04" />
      </inertial>
      <visual>
        <origin rpy="-2.0 0 1.5708" xyz="0.27 -0.66 0.011"/>
        <geometry>
          <mesh filename="package://lite3_description/meshes/L_THIGH.dae" />
        </geometry>
      </visual>
      <collision>
        <origin xyz="0 0 -0.08"/>
        <geometry>
          <box size="0.02 0.02 0.16"/>
        </geometry>
      </collision>
    </link>

    <joint name="HL_HipY" type="revolute">
      <origin xyz="0 0.0985 0" />
      <parent link="HL_HIP" />
      <child link="HL_THIGH" />
      <axis xyz="0 -1 0" />
      <limit lower="-2.67" upper="0.314" effort="40" velocity="30" />
       <dynamics damping="2" friction="6.5"/>
    </joint>

    <link name="HL_SHANK">
      <inertial>
        <origin xyz="0.00585 -8.732E-07 -0.12" />
        <mass value="0.115" />
        <inertia ixx="6.68E-04" ixy="-1.24E-08" ixz="6.91E-06" iyy="6.86E-04" iyz="5.65E-09" izz="3.155E-05" />
      </inertial>
      <visual>
      <origin xyz="0 0 -0.03"/>
        <geometry>
          <mesh filename="package://lite3_description/meshes/SHANK.dae" />
        </geometry>
      </visual>
      <collision>
        <origin xyz="0 0 -0.09"/>
        <geometry>
          <box size="0.02 0.02 0.20"/>
        </geometry>
      </collision>
    </link>

    <joint name="HL_Knee" type="revolute">
      <origin xyz="0 0 -0.20" />
      <parent link="HL_THIGH" />
      <child link="HL_SHANK" />
      <axis xyz="0 -1 0" />
      <limit lower="0.524" upper="2.792" effort="65" velocity="20" />
       <dynamics damping="2" friction="6.5"/>
    </joint>

    <link name="HL_FOOT">
      <inertial>
        <mass value="1E-12" />
        <inertia ixx="1E-12" ixy="0" ixz="0" iyy="1E-12" iyz="0" izz="1E-12" />
      </inertial>
      <collision>
        <geometry>
          <sphere radius="0.013"/>
        </geometry>
      </collision>
    </link>

    <joint name="HL_Ankle" type="fixed">
      <origin xyz="0 0 -0.21"/>
      <parent link="HL_SHANK" />
      <child link="HL_FOOT" />
    </joint>

    <link name="HR_HIP">
      <inertial>
        <origin xyz="0.0047 0.0091 -0.0018" />
        <mass value="0.428" />
        <inertia ixx="0.00014538" ixy="8.1545E-07" ixz="1.2639E-05" iyy="0.00024024" iyz="-1.344E-06" izz="0.00013038" />
      </inertial>
      <visual>
        <origin rpy="1.5708 0 1.5708" xyz="0.13 -0.445 0.09"/>
        <geometry>
          <mesh filename="package://lite3_description/meshes/HR_HIP.dae" />
        </geometry>
      </visual>
    </link>

    <joint name="HR_HipX" type="revolute">
      <origin xyz="-0.1745 -0.062 0" />
      <parent link="TORSO" />
      <child link="HR_HIP" />
      <axis xyz="-1 0 0" />
      <limit lower="-0.523" upper="0.523" effort="40" velocity="30" />
       <dynamics damping="2" friction="6.5"/>
    </joint>

    <link name="HR_THIGH">
      <inertial>
        <origin xyz="-0.00523 0.0216 -0.0273" />
        <mass value="0.61" />
        <inertia ixx="0.001" ixy="2.5E-06" ixz="-1.12E-04" iyy="0.00116" iyz="-3.75E-07" izz="2.68E-04" />
      </inertial>
      <visual>
        <origin rpy="-2.0 0 1.5708" xyz="0.27 -0.35 0.013"/>
        <geometry>
          <mesh filename="package://lite3_description/meshes/R_THIGH.dae" />
        </geometry>
      </visual>
      <collision>
        <origin xyz="0 0 -0.08"/>
        <geometry>
          <box size="0.02 0.02 0.16"/>
        </geometry>
      </collision>
    </link>

    <joint name="HR_HipY" type="revolute">
      <origin xyz="0 -0.0985 0" />
      <parent link="HR_HIP" />
      <child link="HR_THIGH" />
      <axis xyz="0 -1 0" />
      <limit lower="-2.67" upper="0.314" effort="40" velocity="30" />
       <dynamics damping="2" friction="6.5"/>
    </joint>

    <link name="HR_SHANK">
      <inertial>
        <origin xyz="0.00585 -8.732E-07 -0.12" />
        <mass value="0.115" />
        <inertia ixx="6.68E-04" ixy="-1.24E-08" ixz="6.91E-06" iyy="6.86E-04" iyz="5.65E-09" izz="3.155E-05" />
      </inertial>
      <visual>
        <origin xyz="0 0 -0.03"/>
        <geometry>
          <mesh filename="package://lite3_description/meshes/SHANK.dae" />
        </geometry>
      </visual>
      <collision>
        <origin xyz="0 0 -0.09"/>
        <geometry>
          <box size="0.02 0.02 0.20"/>
        </geometry>
      </collision>
    </link>

    <joint name="HR_Knee" type="revolute">
      <origin xyz="0 0 -0.20" />
      <parent link="HR_THIGH" />
      <child link="HR_SHANK" />
      <axis xyz="0 -1 0" />
      <limit lower="0.524" upper="2.792" effort="65" velocity="20" />
       <dynamics damping="2" friction="6.5"/>
    </joint>

    <link name="HR_FOOT">
      <inertial>
        <mass value="1E-12" />
        <inertia ixx="1E-12" ixy="0" ixz="0" iyy="1E-12" iyz="0" izz="1E-12" />
      </inertial>
      <collision>
        <geometry>
          <sphere radius="0.013"/>
        </geometry>
      </collision>
    </link>

    <joint name="HR_Ankle" type="fixed">
      <origin xyz="0 0 -0.21"/>
      <parent link="HR_SHANK" />
      <child link="HR_FOOT" />
    </joint>

    <!-- Lidar -->
      <xacro:if value="${has_lidar}">
        <joint name="lidar_base_mount_joint" type="fixed">
          <origin xyz="0.1745 0 0.05"/>
          <parent link="TORSO"/>
          <child link="lidar_base_link"/>
        </joint>
        <link name="lidar_base_link">
          <inertial>
            <mass value="1e-7"/>
            <origin xyz="0 0 0.03585"/>
            <inertia ixx="1e-7" ixy="0" ixz="0" iyy="1e-7" iyz="0" izz="1e-7"/>
          </inertial>
          <visual>
            <geometry>
              <mesh filename="package://velodyne_description/meshes/VLP16_base_1.dae" />
            </geometry>
          </visual>
          <visual>
            <geometry>
              <mesh filename="package://velodyne_description/meshes/VLP16_base_2.dae" />
            </geometry>
          </visual>
          <collision>
            <origin rpy="0 0 0" xyz="0 0 0.03585"/>
            <geometry>
              <cylinder radius="0.0516" length="0.0717"/>
            </geometry>
          </collision>
        </link>
        <joint name="lidar_base_scan_joint" type="fixed" >
          <origin xyz="0 0 0.0377" rpy="0 0 0" />
          <parent link="lidar_base_link" />
          <child link="lidar_link"/>
        </joint>
        <link name="lidar_link">
          <inertial>
            <mass value="1e-7"/>
            <origin xyz="0 0 0"/>
            <inertia ixx="1e-7" ixy="0" ixz="0" iyy="1e-7" iyz="0" izz="1e-7"/>
          </inertial>
          <visual>
            <origin xyz="0 0 -0.0377" />
            <geometry>
              <mesh filename="package://velodyne_description/meshes/VLP16_scan.dae" />
            </geometry>
          </visual>
          <collision>
            <geometry>
              <sphere radius="0"/>
            </geometry>
          </collision>
        </link>
        <gazebo reference="lidar_link">
          <sensor type="gpu_ray" name="velodyne-VLP16">
            <pose>0 0 0 0 0 0</pose>
            <visualize>false</visualize>
            <update_rate>${lidar_hz}</update_rate>
            <ray>
              <scan>
                <horizontal>
                  <samples>${lidar_horizontal_samples}</samples>
                  <resolution>1</resolution>
                  <min_angle>-${M_PI}</min_angle>
                  <max_angle>${M_PI}</max_angle>
                </horizontal>
                <vertical>
                  <samples>${lidar_channels}</samples>
                  <resolution>1</resolution>
                  <min_angle>-${15.0*M_PI/180.0}</min_angle>
                  <max_angle> ${15.0*M_PI/180.0}</max_angle>
                </vertical>
              </scan>
              <range>
                <min>0.3</min>
                <max>${lidar_max_range+1}</max>
                <resolution>0.001</resolution>
              </range>
              <noise>
                <type>gaussian</type>
                <mean>0.0</mean>
                <stddev>0.0</stddev>
              </noise>
            </ray>
            <plugin name="gazebo_ros_laser_controller" filename="libgazebo_ros_velodyne_gpu_laser.so">
              <robotNamespace>lite3_gazebo</robotNamespace>
              <topicName>point_cloud</topicName>
              <frameName>/lidar_link</frameName>
              <organize_cloud>false</organize_cloud>
              <min_range>${lidar_min_range}</min_range>
              <max_range>${lidar_max_range}</max_range>
              <gaussianNoise>${lidar_noise}</gaussianNoise>
            </plugin>
          </sensor>
        </gazebo>
      </xacro:if>
    </xacro:macro>
</robot>
